[2024-09-12T19:00:24.413+0000] {local_task_job_runner.py:123} INFO - ::group::Pre task execution logs
[2024-09-12T19:00:24.426+0000] {taskinstance.py:2612} INFO - Dependencies all met for dep_context=non-requeueable deps ti=<TaskInstance: snowflake_automation_dag.snowflake_load manual__2024-09-12T18:06:56.514228+00:00 [queued]>
[2024-09-12T19:00:24.431+0000] {taskinstance.py:2612} INFO - Dependencies all met for dep_context=requeueable deps ti=<TaskInstance: snowflake_automation_dag.snowflake_load manual__2024-09-12T18:06:56.514228+00:00 [queued]>
[2024-09-12T19:00:24.432+0000] {taskinstance.py:2865} INFO - Starting attempt 4 of 4
[2024-09-12T19:00:24.438+0000] {taskinstance.py:2888} INFO - Executing <Task(SnowflakeOperator): snowflake_load> on 2024-09-12 18:06:56.514228+00:00
[2024-09-12T19:00:24.445+0000] {warnings.py:112} WARNING - /home/***/.local/lib/python3.12/site-packages/***/task/task_runner/standard_task_runner.py:70: DeprecationWarning: This process (pid=2093) is multi-threaded, use of fork() may lead to deadlocks in the child.
  pid = os.fork()

[2024-09-12T19:00:24.447+0000] {standard_task_runner.py:72} INFO - Started process 2095 to run task
[2024-09-12T19:00:24.448+0000] {standard_task_runner.py:104} INFO - Running: ['***', 'tasks', 'run', 'snowflake_automation_dag', 'snowflake_load', 'manual__2024-09-12T18:06:56.514228+00:00', '--job-id', '36', '--raw', '--subdir', 'DAGS_FOLDER/***_emr_spark_s3_snowflake.py', '--cfg-path', '/tmp/tmpl4rs9q74']
[2024-09-12T19:00:24.451+0000] {standard_task_runner.py:105} INFO - Job 36: Subtask snowflake_load
[2024-09-12T19:00:24.495+0000] {task_command.py:467} INFO - Running <TaskInstance: snowflake_automation_dag.snowflake_load manual__2024-09-12T18:06:56.514228+00:00 [running]> on host 70476fe7f1d5
[2024-09-12T19:00:24.546+0000] {taskinstance.py:3131} INFO - Exporting env vars: AIRFLOW_CTX_DAG_OWNER='Airflow' AIRFLOW_CTX_DAG_ID='snowflake_automation_dag' AIRFLOW_CTX_TASK_ID='snowflake_load' AIRFLOW_CTX_EXECUTION_DATE='2024-09-12T18:06:56.514228+00:00' AIRFLOW_CTX_TRY_NUMBER='4' AIRFLOW_CTX_DAG_RUN_ID='manual__2024-09-12T18:06:56.514228+00:00'
[2024-09-12T19:00:24.548+0000] {taskinstance.py:731} INFO - ::endgroup::
[2024-09-12T19:00:24.559+0000] {sql.py:266} INFO - Executing: ALTER EXTERNAL TABLE s3_to_snowflake.PUBLIC.Iris_dataset REFRESH
[2024-09-12T19:00:24.570+0000] {base.py:84} INFO - Retrieving connection 'snowflake_conn'
[2024-09-12T19:00:24.579+0000] {base.py:84} INFO - Retrieving connection 'snowflake_conn'
[2024-09-12T19:00:24.581+0000] {connection.py:413} INFO - Snowflake Connector for Python Version: 3.12.1, Python Version: 3.12.5, Platform: Linux-5.15.49-linuxkit-aarch64-with-glibc2.36
[2024-09-12T19:00:24.582+0000] {connection.py:1196} INFO - Connecting to GLOBAL Snowflake domain
[2024-09-12T19:00:24.582+0000] {connection.py:1277} INFO - This connection is in OCSP Fail Open Mode. TLS Certificates would be checked for validity and revocation status. Any other Certificate Revocation related exceptions or OCSP Responder failures would be disregarded in favor of connectivity.
[2024-09-12T19:00:25.734+0000] {cursor.py:1156} INFO - Number of results in first chunk: 1
[2024-09-12T19:00:25.736+0000] {sql.py:509} INFO - Running statement: ALTER EXTERNAL TABLE s3_to_snowflake.PUBLIC.Iris_dataset REFRESH, parameters: None
[2024-09-12T19:00:25.856+0000] {connection.py:788} INFO - closed
[2024-09-12T19:00:25.933+0000] {connection.py:794} INFO - No async queries seem to be running, deleting session
[2024-09-12T19:00:26.018+0000] {taskinstance.py:3310} ERROR - Task failed with exception
Traceback (most recent call last):
  File "/home/airflow/.local/lib/python3.12/site-packages/airflow/models/taskinstance.py", line 767, in _execute_task
    result = _execute_callable(context=context, **execute_callable_kwargs)
             ^^^^^^^^^^^^^^^^^^^^^^^^^^^^^^^^^^^^^^^^^^^^^^^^^^^^^^^^^^^^^
  File "/home/airflow/.local/lib/python3.12/site-packages/airflow/models/taskinstance.py", line 733, in _execute_callable
    return ExecutionCallableRunner(
           ^^^^^^^^^^^^^^^^^^^^^^^^
  File "/home/airflow/.local/lib/python3.12/site-packages/airflow/utils/operator_helpers.py", line 252, in run
    return self.func(*args, **kwargs)
           ^^^^^^^^^^^^^^^^^^^^^^^^^^
  File "/home/airflow/.local/lib/python3.12/site-packages/airflow/models/baseoperator.py", line 406, in wrapper
    return func(self, *args, **kwargs)
           ^^^^^^^^^^^^^^^^^^^^^^^^^^^
  File "/home/airflow/.local/lib/python3.12/site-packages/airflow/providers/common/sql/operators/sql.py", line 272, in execute
    output = hook.run(
             ^^^^^^^^^
  File "/home/airflow/.local/lib/python3.12/site-packages/airflow/providers/snowflake/hooks/snowflake.py", line 410, in run
    self._run_command(cur, sql_statement, parameters)  # type: ignore[attr-defined]
    ^^^^^^^^^^^^^^^^^^^^^^^^^^^^^^^^^^^^^^^^^^^^^^^^^
  File "/home/airflow/.local/lib/python3.12/site-packages/airflow/providers/common/sql/hooks/sql.py", line 514, in _run_command
    cur.execute(sql_statement)
  File "/home/airflow/.local/lib/python3.12/site-packages/snowflake/connector/cursor.py", line 1087, in execute
    Error.errorhandler_wrapper(self.connection, self, error_class, errvalue)
  File "/home/airflow/.local/lib/python3.12/site-packages/snowflake/connector/errors.py", line 284, in errorhandler_wrapper
    handed_over = Error.hand_to_other_handler(
                  ^^^^^^^^^^^^^^^^^^^^^^^^^^^^
  File "/home/airflow/.local/lib/python3.12/site-packages/snowflake/connector/errors.py", line 339, in hand_to_other_handler
    cursor.errorhandler(connection, cursor, error_class, error_value)
  File "/home/airflow/.local/lib/python3.12/site-packages/snowflake/connector/errors.py", line 215, in default_errorhandler
    raise error_class(
snowflake.connector.errors.ProgrammingError: 002003 (02000): 01b6fcb4-3202-8c69-0005-b63a0002e316: SQL compilation error:
Database 'S3_TO_SNOWFLAKE' does not exist or not authorized.
[2024-09-12T19:00:26.040+0000] {taskinstance.py:1225} INFO - Marking task as FAILED. dag_id=snowflake_automation_dag, task_id=snowflake_load, run_id=manual__2024-09-12T18:06:56.514228+00:00, execution_date=20240912T180656, start_date=20240912T190024, end_date=20240912T190026
[2024-09-12T19:00:26.055+0000] {taskinstance.py:340} INFO - ::group::Post task execution logs
[2024-09-12T19:00:26.056+0000] {standard_task_runner.py:124} ERROR - Failed to execute job 36 for task snowflake_load (002003 (02000): 01b6fcb4-3202-8c69-0005-b63a0002e316: SQL compilation error:
Database 'S3_TO_SNOWFLAKE' does not exist or not authorized.; 2095)
Traceback (most recent call last):
  File "/home/airflow/.local/lib/python3.12/site-packages/airflow/task/task_runner/standard_task_runner.py", line 117, in _start_by_fork
    ret = args.func(args, dag=self.dag)
          ^^^^^^^^^^^^^^^^^^^^^^^^^^^^^
  File "/home/airflow/.local/lib/python3.12/site-packages/airflow/cli/cli_config.py", line 49, in command
    return func(*args, **kwargs)
           ^^^^^^^^^^^^^^^^^^^^^
  File "/home/airflow/.local/lib/python3.12/site-packages/airflow/utils/cli.py", line 115, in wrapper
    return f(*args, **kwargs)
           ^^^^^^^^^^^^^^^^^^
  File "/home/airflow/.local/lib/python3.12/site-packages/airflow/cli/commands/task_command.py", line 483, in task_run
    task_return_code = _run_task_by_selected_method(args, _dag, ti)
                       ^^^^^^^^^^^^^^^^^^^^^^^^^^^^^^^^^^^^^^^^^^^^
  File "/home/airflow/.local/lib/python3.12/site-packages/airflow/cli/commands/task_command.py", line 256, in _run_task_by_selected_method
    return _run_raw_task(args, ti)
           ^^^^^^^^^^^^^^^^^^^^^^^
  File "/home/airflow/.local/lib/python3.12/site-packages/airflow/cli/commands/task_command.py", line 341, in _run_raw_task
    return ti._run_raw_task(
           ^^^^^^^^^^^^^^^^^
  File "/home/airflow/.local/lib/python3.12/site-packages/airflow/utils/session.py", line 97, in wrapper
    return func(*args, session=session, **kwargs)
           ^^^^^^^^^^^^^^^^^^^^^^^^^^^^^^^^^^^^^^
  File "/home/airflow/.local/lib/python3.12/site-packages/airflow/models/taskinstance.py", line 3004, in _run_raw_task
    return _run_raw_task(
           ^^^^^^^^^^^^^^
  File "/home/airflow/.local/lib/python3.12/site-packages/airflow/models/taskinstance.py", line 273, in _run_raw_task
    TaskInstance._execute_task_with_callbacks(
  File "/home/airflow/.local/lib/python3.12/site-packages/airflow/models/taskinstance.py", line 3158, in _execute_task_with_callbacks
    result = self._execute_task(context, task_orig)
             ^^^^^^^^^^^^^^^^^^^^^^^^^^^^^^^^^^^^^^
  File "/home/airflow/.local/lib/python3.12/site-packages/airflow/models/taskinstance.py", line 3182, in _execute_task
    return _execute_task(self, context, task_orig)
           ^^^^^^^^^^^^^^^^^^^^^^^^^^^^^^^^^^^^^^^
  File "/home/airflow/.local/lib/python3.12/site-packages/airflow/models/taskinstance.py", line 767, in _execute_task
    result = _execute_callable(context=context, **execute_callable_kwargs)
             ^^^^^^^^^^^^^^^^^^^^^^^^^^^^^^^^^^^^^^^^^^^^^^^^^^^^^^^^^^^^^
  File "/home/airflow/.local/lib/python3.12/site-packages/airflow/models/taskinstance.py", line 733, in _execute_callable
    return ExecutionCallableRunner(
           ^^^^^^^^^^^^^^^^^^^^^^^^
  File "/home/airflow/.local/lib/python3.12/site-packages/airflow/utils/operator_helpers.py", line 252, in run
    return self.func(*args, **kwargs)
           ^^^^^^^^^^^^^^^^^^^^^^^^^^
  File "/home/airflow/.local/lib/python3.12/site-packages/airflow/models/baseoperator.py", line 406, in wrapper
    return func(self, *args, **kwargs)
           ^^^^^^^^^^^^^^^^^^^^^^^^^^^
  File "/home/airflow/.local/lib/python3.12/site-packages/airflow/providers/common/sql/operators/sql.py", line 272, in execute
    output = hook.run(
             ^^^^^^^^^
  File "/home/airflow/.local/lib/python3.12/site-packages/airflow/providers/snowflake/hooks/snowflake.py", line 410, in run
    self._run_command(cur, sql_statement, parameters)  # type: ignore[attr-defined]
    ^^^^^^^^^^^^^^^^^^^^^^^^^^^^^^^^^^^^^^^^^^^^^^^^^
  File "/home/airflow/.local/lib/python3.12/site-packages/airflow/providers/common/sql/hooks/sql.py", line 514, in _run_command
    cur.execute(sql_statement)
  File "/home/airflow/.local/lib/python3.12/site-packages/snowflake/connector/cursor.py", line 1087, in execute
    Error.errorhandler_wrapper(self.connection, self, error_class, errvalue)
  File "/home/airflow/.local/lib/python3.12/site-packages/snowflake/connector/errors.py", line 284, in errorhandler_wrapper
    handed_over = Error.hand_to_other_handler(
                  ^^^^^^^^^^^^^^^^^^^^^^^^^^^^
  File "/home/airflow/.local/lib/python3.12/site-packages/snowflake/connector/errors.py", line 339, in hand_to_other_handler
    cursor.errorhandler(connection, cursor, error_class, error_value)
  File "/home/airflow/.local/lib/python3.12/site-packages/snowflake/connector/errors.py", line 215, in default_errorhandler
    raise error_class(
snowflake.connector.errors.ProgrammingError: 002003 (02000): 01b6fcb4-3202-8c69-0005-b63a0002e316: SQL compilation error:
Database 'S3_TO_SNOWFLAKE' does not exist or not authorized.
[2024-09-12T19:00:26.084+0000] {local_task_job_runner.py:266} INFO - Task exited with return code 1
[2024-09-12T19:00:26.099+0000] {taskinstance.py:3900} INFO - 0 downstream tasks scheduled from follow-on schedule check
[2024-09-12T19:00:26.100+0000] {local_task_job_runner.py:245} INFO - ::endgroup::
